Workbook

Sheet Raw_Data
A1: Apple Inc. — Financial Statement Raw Data (FY2021–FY2025)
A2: Source: Apple Inc. Form 10-K filings, SEC EDGAR (CIK 0000320193) — $ in millions, fiscal year ended late September
A4: Line Item | B4: FY2021 | C4: FY2022 | D4: FY2023 | E4: FY2024 | F4: FY2025
A6: INCOME STATEMENT
A7: Revenue | B7: 365817 | C7: 394328 | D7: 383285 | E7: 391035 | F7: 416161
A8: Cost of Sales | B8: 212981 | C8: 223546 | D8: 214137 | E8: 210352 | F8: 220960
A9: Gross Profit | B9: 152836 | C9: 170782 | D9: 169148 | E9: 180683 | F9: 195201
A10: Research & Development | B10: 21914 | C10: 26251 | D10: 29915 | E10: 31370 | F10: 34550
A11: Selling, General & Administrative | B11: 21973 | C11: 25094 | D11: 24932 | E11: 26097 | F11: 27601
A12: Total Operating Expenses | B12: 43887 | C12: 51345 | D12: 54847 | E12: 57467 | F12: 62151
A13: Operating Income | B13: 108949 | C13: 119437 | D13: 114301 | E13: 123216 | F13: 133050
A14: Net Income | B14: 94680 | C14: 99803 | D14: 96995 | E14: 93736 | F14: 112010
A16: BALANCE SHEET
A17: Cash & Equivalents | B17: 34940 | C17: 23646 | D17: 29965 | E17: 29943 | F17: 35934
A18: Inventory | B18: 6580 | C18: 4946 | D18: 6331 | E18: 7286 | F18: 5718
A19: Total Current Assets | B19: 134836 | C19: 135405 | D19: 143566 | E19: 152987 | F19: 147957
A20: Total Assets | B20: 351002 | C20: 352755 | D20: 352583 | E20: 364980 | F20: 359241
A21: Total Current Liabilities | B21: 125481 | C21: 153982 | D21: 145308 | E21: 176392 | F21: 165631
A22: Total Liabilities | B22: 287912 | C22: 302083 | D22: 290437 | E22: 308030 | F22: 285508
A23: Total Shareholders' Equity | B23: 63090 | C23: 50672 | D23: 62146 | E23: 56950 | F23: 73733
A25: CASH FLOW STATEMENT
A26: Operating Cash Flow | B26: 104038 | C26: 122151 | D26: 110543 | E26: 118254 | F26: 111482
A27: Investing Cash Flow | B27: -14545 | C27: -22354 | D27: 3705 | E27: 2935 | F27: 15195
A28: Financing Cash Flow | B28: -93353 | C28: -110749 | D28: -108488 | E28: -121983 | F28: -120686
A29: Capital Expenditures | B29: -11085 | C29: -10708 | D29: -10959 | E29: -9447 | F29: -12715
A30: Free Cash Flow | B30: 92953 | C30: 111443 | D30: 99584 | E30: 108807 | F30: 98767
A32: Note: Cost of Sales for FY2024/FY2025 derived as Revenue − Gross Profit (not pulled as a discrete 10-K line item).

Sheet Ratios
A1: Apple Inc. — Financial Ratio Analysis (FY2021–FY2025)
A3: Ratio | B3: FY2021 | C3: FY2022 | D3: FY2023 | E3: FY2024 | F3: FY2025
A5: LIQUIDITY RATIOS
A6: Current Ratio | B6: =Raw_Data!B19/Raw_Data!B21 -> 1.0745531 | C6: =Raw_Data!C19/Raw_Data!C21 -> 0.87935603 | D6: =Raw_Data!D19/Raw_Data!D21 -> 0.98801167 | E6: =Raw_Data!E19/Raw_Data!E21 -> 0.86731258 | F6: =Raw_Data!F19/Raw_Data!F21 -> 0.89329292
A7: Cash Ratio | B7: =Raw_Data!B17/Raw_Data!B21 -> 0.27844853 | C7: =Raw_Data!C17/Raw_Data!C21 -> 0.1535634 | D7: =Raw_Data!D17/Raw_Data!D21 -> 0.20621714 | E7: =Raw_Data!E17/Raw_Data!E21 -> 0.1697526 | F7: =Raw_Data!F17/Raw_Data!F21 -> 0.21695214
A9: PROFITABILITY RATIOS
A10: Gross Margin | B10: =Raw_Data!B9/Raw_Data!B7 -> 0.4177936 | C10: =Raw_Data!C9/Raw_Data!C7 -> 0.43309631 | D10: =Raw_Data!D9/Raw_Data!D7 -> 0.4413113 | E10: =Raw_Data!E9/Raw_Data!E7 -> 0.4620635 | F10: =Raw_Data!F9/Raw_Data!F7 -> 0.46905164
A11: Operating Margin | B11: =Raw_Data!B13/Raw_Data!B7 -> 0.29782378 | C11: =Raw_Data!C13/Raw_Data!C7 -> 0.30288744 | D11: =Raw_Data!D13/Raw_Data!D7 -> 0.29821412 | E11: =Raw_Data!E13/Raw_Data!E7 -> 0.31510223 | F11: =Raw_Data!F13/Raw_Data!F7 -> 0.319708
A12: Net Margin | B12: =Raw_Data!B14/Raw_Data!B7 -> 0.25881793 | C12: =Raw_Data!C14/Raw_Data!C7 -> 0.25309641 | D12: =Raw_Data!D14/Raw_Data!D7 -> 0.25306234 | E12: =Raw_Data!E14/Raw_Data!E7 -> 0.23971256 | F12: =Raw_Data!F14/Raw_Data!F7 -> 0.26915064
A13: Return on Assets (ROA) | B13: =Raw_Data!B14/Raw_Data!B20 -> 0.26974205 | C13: =Raw_Data!C14/Raw_Data!C20 -> 0.28292441 | D13: =Raw_Data!D14/Raw_Data!D20 -> 0.27509835 | E13: =Raw_Data!E14/Raw_Data!E20 -> 0.25682503 | F13: =Raw_Data!F14/Raw_Data!F20 -> 0.31179626
A14: Return on Equity (ROE) | B14: =Raw_Data!B14/Raw_Data!B23 -> 1.5007133 | C14: =Raw_Data!C14/Raw_Data!C23 -> 1.9695887 | D14: =Raw_Data!D14/Raw_Data!D23 -> 1.5607601 | E14: =Raw_Data!E14/Raw_Data!E23 -> 1.645935 | F14: =Raw_Data!F14/Raw_Data!F23 -> 1.5191298
A16: LEVERAGE / SOLVENCY RATIOS
A17: Debt-to-Equity (Total Liabilities / Equity) | B17: =Raw_Data!B22/Raw_Data!B23 -> 4.5635124 | C17: =Raw_Data!C22/Raw_Data!C23 -> 5.9615369 | D17: =Raw_Data!D22/Raw_Data!D23 -> 4.6734625 | E17: =Raw_Data!E22/Raw_Data!E23 -> 5.4087796 | F17: =Raw_Data!F22/Raw_Data!F23 -> 3.8721875
A18: Equity Ratio (Equity / Total Assets) | B18: =Raw_Data!B23/Raw_Data!B20 -> 0.17974257 | C18: =Raw_Data!C23/Raw_Data!C20 -> 0.14364644 | D18: =Raw_Data!D23/Raw_Data!D20 -> 0.17625921 | E18: =Raw_Data!E23/Raw_Data!E20 -> 0.15603595 | F18: =Raw_Data!F23/Raw_Data!F20 -> 0.20524662
A20: EFFICIENCY RATIOS
A21: Asset Turnover (Revenue / Total Assets) | B21: =Raw_Data!B7/Raw_Data!B20 -> 1.0422077 | C21: =Raw_Data!C7/Raw_Data!C20 -> 1.1178523 | D21: =Raw_Data!D7/Raw_Data!D20 -> 1.0870774 | E21: =Raw_Data!E7/Raw_Data!E20 -> 1.0713875 | F21: =Raw_Data!F7/Raw_Data!F20 -> 1.1584452
A22: Inventory Turnover (Cost of Sales / Inventory) | B22: =Raw_Data!B8/Raw_Data!B18 -> 32.367933 | C22: =Raw_Data!C8/Raw_Data!C18 -> 45.197331 | D22: =Raw_Data!D8/Raw_Data!D18 -> 33.823567 | E22: =Raw_Data!E8/Raw_Data!E18 -> 28.870711 | F22: =Raw_Data!F8/Raw_Data!F18 -> 38.642882
A24: CASH FLOW RATIOS
A25: Free Cash Flow Margin (FCF / Revenue) | B25: =Raw_Data!B30/Raw_Data!B7 -> 0.25409699 | C25: =Raw_Data!C30/Raw_Data!C7 -> 0.28261498 | D25: =Raw_Data!D30/Raw_Data!D7 -> 0.25981711 | E25: =Raw_Data!E30/Raw_Data!E7 -> 0.27825386 | F25: =Raw_Data!F30/Raw_Data!F7 -> 0.23732882
A26: Operating Cash Flow Ratio (OCF / Current Liabilities) | B26: =Raw_Data!B26/Raw_Data!B21 -> 0.82911357 | C26: =Raw_Data!C26/Raw_Data!C21 -> 0.79328103 | D26: =Raw_Data!D26/Raw_Data!D21 -> 0.76074958 | E26: =Raw_Data!E26/Raw_Data!E21 -> 0.67040455 | F26: =Raw_Data!F26/Raw_Data!F21 -> 0.67307448
A28: All ratios calculated directly from Raw_Data sheet — update figures there and these recalculate automatically.

Sheet PBI_Model
A1: Flat Data Model for Power BI Import
A2: One row per Year x Metric x Value — connect Power BI to this table.
A4: Year | B4: Statement | C4: Metric | D4: Value
A5: FY2021 | B5: Income Statement | C5: Revenue | D5: =Raw_Data!B7 -> 365817
A6: FY2022 | B6: Income Statement | C6: Revenue | D6: =Raw_Data!C7 -> 394328
A7: FY2023 | B7: Income Statement | C7: Revenue | D7: =Raw_Data!D7 -> 383285
A8: FY2024 | B8: Income Statement | C8: Revenue | D8: =Raw_Data!E7 -> 391035
A9: FY2025 | B9: Income Statement | C9: Revenue | D9: =Raw_Data!F7 -> 416161
A10: FY2021 | B10: Income Statement | C10: Cost of Sales | D10: =Raw_Data!B8 -> 212981
A11: FY2022 | B11: Income Statement | C11: Cost of Sales | D11: =Raw_Data!C8 -> 223546
A12: FY2023 | B12: Income Statement | C12: Cost of Sales | D12: =Raw_Data!D8 -> 214137
A13: FY2024 | B13: Income Statement | C13: Cost of Sales | D13: =Raw_Data!E8 -> 210352
A14: FY2025 | B14: Income Statement | C14: Cost of Sales | D14: =Raw_Data!F8 -> 220960
A15: FY2021 | B15: Income Statement | C15: Gross Profit | D15: =Raw_Data!B9 -> 152836
A16: FY2022 | B16: Income Statement | C16: Gross Profit | D16: =Raw_Data!C9 -> 170782
A17: FY2023 | B17: Income Statement | C17: Gross Profit | D17: =Raw_Data!D9 -> 169148
A18: FY2024 | B18: Income Statement | C18: Gross Profit | D18: =Raw_Data!E9 -> 180683
A19: FY2025 | B19: Income Statement | C19: Gross Profit | D19: =Raw_Data!F9 -> 195201
A20: FY2021 | B20: Income Statement | C20: Research & Development | D20: =Raw_Data!B10 -> 21914
A21: FY2022 | B21: Income Statement | C21: Research & Development | D21: =Raw_Data!C10 -> 26251
A22: FY2023 | B22: Income Statement | C22: Research & Development | D22: =Raw_Data!D10 -> 29915
A23: FY2024 | B23: Income Statement | C23: Research & Development | D23: =Raw_Data!E10 -> 31370
A24: FY2025 | B24: Income Statement | C24: Research & Development | D24: =Raw_Data!F10 -> 34550
A25: FY2021 | B25: Income Statement | C25: Selling, General & Administrative | D25: =Raw_Data!B11 -> 21973
A26: FY2022 | B26: Income Statement | C26: Selling, General & Administrative | D26: =Raw_Data!C11 -> 25094
A27: FY2023 | B27: Income Statement | C27: Selling, General & Administrative | D27: =Raw_Data!D11 -> 24932
A28: FY2024 | B28: Income Statement | C28: Selling, General & Administrative | D28: =Raw_Data!E11 -> 26097
A29: FY2025 | B29: Income Statement | C29: Selling, General & Administrative | D29: =Raw_Data!F11 -> 27601
A30: FY2021 | B30: Income Statement | C30: Total Operating Expenses | D30: =Raw_Data!B12 -> 43887
A31: FY2022 | B31: Income Statement | C31: Total Operating Expenses | D31: =Raw_Data!C12 -> 51345
A32: FY2023 | B32: Income Statement | C32: Total Operating Expenses | D32: =Raw_Data!D12 -> 54847
A33: FY2024 | B33: Income Statement | C33: Total Operating Expenses | D33: =Raw_Data!E12 -> 57467
A34: FY2025 | B34: Income Statement | C34: Total Operating Expenses | D34: =Raw_Data!F12 -> 62151
A35: FY2021 | B35: Income Statement | C35: Operating Income | D35: =Raw_Data!B13 -> 108949
A36: FY2022 | B36: Income Statement | C36: Operating Income | D36: =Raw_Data!C13 -> 119437
A37: FY2023 | B37: Income Statement | C37: Operating Income | D37: =Raw_Data!D13 -> 114301
A38: FY2024 | B38: Income Statement | C38: Operating Income | D38: =Raw_Data!E13 -> 123216
A39: FY2025 | B39: Income Statement | C39: Operating Income | D39: =Raw_Data!F13 -> 133050
A40: FY2021 | B40: Income Statement | C40: Net Income | D40: =Raw_Data!B14 -> 94680
A41: FY2022 | B41: Income Statement | C41: Net Income | D41: =Raw_Data!C14 -> 99803
...
